Workbook

Sheet Lisez-moi
B2: Referentiel d'entretien des equipements du logement - France
B3: Base de donnees source pour une application de suivi d'entretien (marche francais)
B5: Objet du document | C5: Recenser les equipements d'un logement francais qui demandent un entretien periodique, decrire le geste d'entretien associe, et distinguer ce qui releve d'une obligation legale de ce qui releve de la bonne pratique. Ce fichier est concu comme le jeu de donnees d'amorcage (seed) d'une application, pas comme un document de lecture.
B6: Onglet Synthese | C6: Compteurs automatiques par categorie, par palier d'abonnement et par type d'intervenant. Toutes les cellules sont des formules : elles se recalculent si vous ajoutez des lignes dans les onglets Equipements et Taches.
B7: Onglet Equipements | C7: 107 equipements. Colonne B : la categorie affichee dans l'application (10 au total). Colonne C : le groupe technique, qui organise le referentiel. C'est le type d'equipement, pas la categorie, qui porte les taches et les obligations. Un equipement = une ligne = une entree du catalogue de l'application. La colonne Priorite MVP indique ce qu'il faut couvrir des la premiere version (1 = indispensable).
B8: Onglet Taches d'entretien | C8: 154 taches rattachees aux equipements par l'identifiant. C'est le coeur du produit : chaque tache porte sa frequence, sa saison, sa duree, ses consommables, son mode operatoire et surtout la consequence si elle n'est pas faite.
B9: Ajout par photo | C9: Onglet Equipements, colonnes O a R : ce qu'il faut photographier (plaque, etiquette datee, cadran ou document), ou le trouver, quels champs lire et que faire si la plaque est inaccessible.
B10: Onglet Plaques par marque | C10: Couche adaptative : des que la marque est connue (saisie ou lue sur le logo), l'application affiche l'emplacement propre au fabricant et valide l'identifiant lu contre le format attendu. Colonne Statut : seules les lignes verifiees sont a pousser en production.
B11: Onglet Obligations legales | C11: 21 obligations reglementaires avec le texte de reference, la frequence, le redevable, le justificatif a conserver et la sanction encourue. Colonnes J a N : les risques en cas de non-conformite, decomposes pour l'affichage (amende, assurance, responsabilite, danger, autre consequence). C'est l'argument commercial le plus solide sur le marche francais : la conformite prime sur la duree de vie dans l'esprit du client.
B12: Onglet Questionnaire | C12: Le questionnaire d'accueil, pose a la premiere utilisation et pour chaque nouveau lieu. Une ligne = une reponse possible, avec les types d'appareil qu'elle cree. Ensuite, les appareils s'ajoutent un par un (photo, facture, saisie). Les textes de cet onglet et les colonnes de risques sont rediges pour l'ecran, donc accentues.
B13: Onglet Referentiel | C13: Nomenclatures a reprendre telles quelles dans le modele de donnees : categories, types de frequence, paliers, statuts de tache, types de justificatif.
B15: Legende des couleurs
B16: Obligation legale | C16: Ligne ou cellule ambre : obligation reglementaire, a traiter en priorite dans le produit.
B17: Tache realisable soi-meme | C17: Vert : tache DIY, eligible au palier gratuit.
B18: Intervention professionnelle | C18: Bleu : necessite un professionnel, matiere du palier Care.
B20: Sources et limites
C21: - Reglementation verifiee en septembre 2026 aupres de service-public.fr, Legifrance, ecologie.gouv.fr et GRDF. Les URL figurent dans l'onglet Obligations legales. La reglementation evolue : prevoir une revue annuelle du referentiel.
C22: - Durees de vie : ordres de grandeur constructeurs et ADEME, pas des engagements. Elles servent a calibrer les alertes de fin de vie, pas a promettre une longevite.
C23: - Couts indicatifs : fourchettes de marche 2026 hors contrat, TTC, variables selon la region et la tension du secteur. A reverifier avant tout affichage de prix dans l'application.
C24: - Les frequences non reglementaires sont des recommandations d'usage courant. Elles doivent etre confrontees a la notice du fabricant pour chaque modele avant d'etre poussees en notification.
C25: - Ce document n'a pas valeur de conseil juridique. Faire valider le volet reglementaire par un juriste avant toute communication commerciale fondee sur la conformite.

Sheet Synthese
B2: Synthese du referentiel
B3: Cellules calculees : elles se mettent a jour si vous ajoutez des lignes.
B5: Categorie | C5: Equipements | D5: dont obligation | E5: Taches | F5: dont DIY | G5: dont Pro
B6: Cuisine | C6: =COUNTIF(Equipements!$B$6:$B$200,$B6) -> 12 | D6: =COUNTIFS(Equipements!$B$6:$B$200,$B6,Equipements!$F$6:$F$200,"Oui*") -> 1 | E6: =COUNTIF(Taches!$D$6:$D$250,$B6) -> 20 | F6: =COUNTIFS(Taches!$D$6:$D$250,$B6,Taches!$F$6:$F$250,"DIY") -> 20 | G6: =COUNTIFS(Taches!$D$6:$D$250,$B6,Taches!$F$6:$F$250,"Pro") -> 0
B7: Buanderie | C7: =COUNTIF(Equipements!$B$6:$B$200,$B7) -> 4 | D7: =COUNTIFS(Equipements!$B$6:$B$200,$B7,Equipements!$F$6:$F$200,"Oui*") -> 0 | E7: =COUNTIF(Taches!$D$6:$D$250,$B7) -> 9 | F7: =COUNTIFS(Taches!$D$6:$D$250,$B7,Taches!$F$6:$F$250,"DIY") -> 9 | G7: =COUNTIFS(Taches!$D$6:$D$250,$B7,Taches!$F$6:$F$250,"Pro") -> 0
B8: Chauffage & climatisation | C8: =COUNTIF(Equipements!$B$6:$B$200,$B8) -> 29 | D8: =COUNTIFS(Equipements!$B$6:$B$200,$B8,Equipements!$F$6:$F$200,"Oui*") -> 15 | E8: =COUNTIF(Taches!$D$6:$D$250,$B8) -> 49 | F8: =COUNTIFS(Taches!$D$6:$D$250,$B8,Taches!$F$6:$F$250,"DIY") -> 24 | G8: =COUNTIFS(Taches!$D$6:$D$250,$B8,Taches!$F$6:$F$250,"Pro") -> 25
B9: Petit electromenager | C9: =COUNTIF(Equipements!$B$6:$B$200,$B9) -> 4 | D9: =COUNTIFS(Equipements!$B$6:$B$200,$B9,Equipements!$F$6:$F$200,"Oui*") -> 0 | E9: =COUNTIF(Taches!$D$6:$D$250,$B9) -> 4 | F9: =COUNTIFS(Taches!$D$6:$D$250,$B9,Taches!$F$6:$F$250,"DIY") -> 4 | G9: =COUNTIFS(Taches!$D$6:$D$250,$B9,Taches!$F$6:$F$250,"Pro") -> 0
B10: Electronique | C10: =COUNTIF(Equipements!$B$6:$B$200,$B10) -> 0 | D10: =COUNTIFS(Equipements!$B$6:$B$200,$B10,Equipements!$F$6:$F$200,"Oui*") -> 0 | E10: =COUNTIF(Taches!$D$6:$D$250,$B10) -> 0 | F10: =COUNTIFS(Taches!$D$6:$D$250,$B10,Taches!$F$6:$F$250,"DIY") -> 0 | G10: =COUNTIFS(Taches!$D$6:$D$250,$B10,Taches!$F$6:$F$250,"Pro") -> 0
B11: Jardin & piscine | C11: =COUNTIF(Equipements!$B$6:$B$200,$B11) -> 15 | D11: =COUNTIFS(Equipements!$B$6:$B$200,$B11,Equipements!$F$6:$F$200,"Oui*") -> 3 | E11: =COUNTIF(Taches!$D$6:$D$250,$B11) -> 20 | F11: =COUNTIFS(Taches!$D$6:$D$250,$B11,Taches!$F$6:$F$250,"DIY") -> 18 | G11: =COUNTIFS(Taches!$D$6:$D$250,$B11,Taches!$F$6:$F$250,"Pro") -> 2
B12: Maison & securite | C12: =COUNTIF(Equipements!$B$6:$B$200,$B12) -> 33 | D12: =COUNTIFS(Equipements!$B$6:$B$200,$B12,Equipements!$F$6:$F$200,"Oui*") -> 5 | E12: =COUNTIF(Taches!$D$6:$D$250,$B12) -> 40 | F12: =COUNTIFS(Taches!$D$6:$D$250,$B12,Taches!$F$6:$F$250,"DIY") -> 30 | G12: =COUNTIFS(Taches!$D$6:$D$250,$B12,Taches!$F$6:$F$250,"Pro") -> 10
B13: Energie | C13: =COUNTIF(Equipements!$B$6:$B$200,$B13) -> 7 | D13: =COUNTIFS(Equipements!$B$6:$B$200,$B13,Equipements!$F$6:$F$200,"Oui*") -> 1 | E13: =COUNTIF(Taches!$D$6:$D$250,$B13) -> 9 | F13: =COUNTIFS(Taches!$D$6:$D$250,$B13,Taches!$F$6:$F$250,"DIY") -> 5 | G13: =COUNTIFS(Taches!$D$6:$D$250,$B13,Taches!$F$6:$F$250,"Pro") -> 4
B14: Vehicules | C14: =COUNTIF(Equipements!$B$6:$B$200,$B14) -> 3 | D14: =COUNTIFS(Equipements!$B$6:$B$200,$B14,Equipements!$F$6:$F$200,"Oui*") -> 2 | E14: =COUNTIF(Taches!$D$6:$D$250,$B14) -> 3 | F14: =COUNTIFS(Taches!$D$6:$D$250,$B14,Taches!$F$6:$F$250,"DIY") -> 0 | G14: =COUNTIFS(Taches!$D$6:$D$250,$B14,Taches!$F$6:$F$250,"Pro") -> 3
B15: Autre | C15: =COUNTIF(Equipements!$B$6:$B$200,$B15) -> 0 | D15: =COUNTIFS(Equipements!$B$6:$B$200,$B15,Equipements!$F$6:$F$200,"Oui*") -> 0 | E15: =COUNTIF(Taches!$D$6:$D$250,$B15) -> 0 | F15: =COUNTIFS(Taches!$D$6:$D$250,$B15,Taches!$F$6:$F$250,"DIY") -> 0 | G15: =COUNTIFS(Taches!$D$6:$D$250,$B15,Taches!$F$6:$F$250,"Pro") -> 0
B16: TOTAL | C16: =SUM(C6:C15) -> 107 | D16: =SUM(D6:D15) -> 27 | E16: =SUM(E6:E15) -> 154 | F16: =SUM(F6:F15) -> 110 | G16: =SUM(G6:G15) -> 44
B19: Repartition par palier d'abonnement
B20: Palier | C20: Nb de taches | D20: % du total
B21: Gratuit | C21: =COUNTIF(Taches!$O$6:$O$250,$B21) -> 128 | D21: =IFERROR(C21/COUNTA(Taches!$A$6:$A$250),0) -> 0.83116883 | E21: Rappels + mode operatoire
B22: Plus | C22: =COUNTIF(Taches!$O$6:$O$250,$B22) -> 19 | D22: =IFERROR(C22/COUNTA(Taches!$A$6:$A$250),0) -> 0.12337662 | E22: Multi-biens, coffre-fort de documents
B23: Care | C23: =COUNTIF(Taches!$O$6:$O$250,$B23) -> 7 | D23: =IFERROR(C23/COUNTA(Taches!$A$6:$A$250),0) -> 0.045454545 | E23: Intervention a domicile
B26: Indicateurs cles
B27: Taches soumises a obligation legale | C27: =COUNTIF(Taches!$N$6:$N$250,"Oui*") -> 31
B28: Taches realisables par l'occupant | C28: =COUNTIF(Taches!$F$6:$F$250,"DIY") -> 110
B29: Taches necessitant un professionnel | C29: =COUNTIF(Taches!$F$6:$F$250,"Pro") -> 44
B30: Equipements a couvrir des le MVP (priorite 1) | C30: =COUNTIF(Equipements!$N$6:$N$200,1) -> 37
B31: Temps DIY cumule sur un an (heures) | C31: =IFERROR(SUMPRODUCT((Taches!$F$6:$F$250="DIY")*(Taches!$G$6:$G$250>0)*Taches!$J$6:$J$250*(12/IF(Taches!$G$6:$G$250=0,1,Taches!$G$6:$G$250)))/60,0) -> 199.66389
B33: Le temps DIY cumule suppose un logement equipe de la totalite du referentiel : c'est un majorant, utile pour dimensionner la charge percue, pas une moyenne de marche.
B36: Ajout par photo : que photographier ?
B37: Cible photo | C37: Equipements | D37: % du catalogue
B38: Plaque signaletique | C38: =COUNTIF(Equipements!$O$6:$O$200,$B38) -> 0 | D38: =IFERROR(C38/COUNTA(Equipements!$A$6:$A$200),0) -> 0
B39: Etiquette datee | C39: =COUNTIF(Equipements!$O$6:$O$200,$B39) -> 0 | D39: =IFERROR(C39/COUNTA(Equipements!$A$6:$A$200),0) -> 0
B40: Cadran | C40: =COUNTIF(Equipements!$O$6:$O$200,$B40) -> 1 | D40: =IFERROR(C40/COUNTA(Equipements!$A$6:$A$200),0) -> 0.0093457944
B41: Document | C41: =COUNTIF(Equipements!$O$6:$O$200,$B41) -> 15 | D41: =IFERROR(C41/COUNTA(Equipements!$A$6:$A$200),0) -> 0.14018692
B42: Aucune | C42: =COUNTIF(Equipements!$O$6:$O$200,$B42) -> 11 | D42: =IFERROR(C42/COUNTA(Equipements!$A$6:$A$200),0) -> 0.10280374

Sheet Equipements
A2: Catalogue des equipements
A3: Un equipement = une entree du catalogue produit. La colonne Nb de taches est calculee.
A5: ID | B5: Categorie | C5: Groupe technique | D5: Equipement | E5: Duree de vie | F5: Obligation legale | G5: Reference reglementaire | H5: Frequence de reference | I5: Intervenant | J5: Justificatif a conserver | K5: Cout pro indicatif | L5: Enjeu si neglige | M5: Nb de taches | N5: Priorite MVP | O5: Cible photo | P5: Ou trouver la plaque (generique) | Q5: Champs a lire | R5: Astuce / alternative
A6: CH-01 | B6: Chauffage & climatisation | C6: Chauffage | D6: Chaudière gaz individuelle (4-400 kW) | E6: 15-20 ans | F6: Oui | G6: Décret 2009-649 + arrêté 15/09/2009 (C. env. R224-41-4 s.) | H6: Annuel | I6: Pro qualifié (PG) | J6: Attestation d'entretien (remise sous 15 j) | K6: 100-180 EUR | L6: Intoxication au CO, refus de prise en charge assurance, surconsommation 10-15% | M6: =COUNTIF(Taches!$B$6:$B$250,$A6) -> 3 | N6: 1 | O6: Plaque signalétique | P6: Sous l'appareil ou derrière le capot avant ; parfois sur le flanc | Q6: Marque, modèle, n. de série, puissance nominale (kW), type de gaz, année | R6: Ne jamais déposer le capot d'un appareil gaz. Alternative : attestation d'entretien ou facture de l'installateur
A7: CH-02 | B7: Chauffage & climatisation | C7: Chauffage | D7: Chaudière fioul | E7: 20-25 ans | F7: Oui | G7: Décret 2009-649 + arrêté 15/09/2009 | H7: Annuel | I7: Pro qualifié | J7: Attestation d'entretien | K7: 130-220 EUR | L7: Encrassement du brûleur, pannes hivernales, refus assurance | M7: =COUNTIF(Taches!$B$6:$B$250,$A7) -> 2 | N7: 1 | O7: Plaque signalétique | P7: Flanc ou porte de façade de la chaudière ; plaque distincte sur le brûleur | Q7: Marque, modèle, n. de série, puissance (kW) ; modèle du brûleur | R7: Deux plaques à photographier : chaudière et brûleur
A8: CH-03 | B8: Chauffage & climatisation | C8: Chauffage | D8: Chaudière bois / granules | E8: 15-20 ans | F8: Oui | G8: Décret 2009-649 ; décret 2023-641 (entretien + ramonage) | H8: Annuel | I8: Pro qualifié | J8: Attestation d'entretien + certificat de ramonage | K8: 150-280 EUR | L8: Feu de conduit, émissions de particules, perte de rendement | M8: =COUNTIF(Taches!$B$6:$B$250,$A8) -> 2 | N8: 1 | O8: Plaque signalétique | P8: Flanc ou arrière de l'appareil, parfois sous le capot du silo | Q8: Marque, modèle, n. de série, puissance (kW), combustible | R8: Alternative : attestation d'entretien
A9: CH-04 | B9: Chauffage & climatisation | C9: Chauffage | D9: Poêle à granules | E9: 15-20 ans | F9: Oui | G9: Décret 2023-641 (entretien 12 mois) + ramonage | H9: Annuel | I9: Pro qualifié | J9: Attestation d'entretien + certificat de ramonage | K9: 120-200 EUR | L9: Encrassement du creuset, arrêt en pleine saison, feu de conduit | M9: =COUNTIF(Taches!$B$6:$B$250,$A9) -> 4 | N9: 1 | O9: Plaque signalétique | P9: Au dos de l'appareil ; parfois sous le couvercle du réservoir à granules | Q9: Marque, modèle, n. de série, puissance (kW), norme EN 14785 | R9: Ne pas déplacer un poêle raccordé : utiliser la notice ou la facture
A10: CH-05 | B10: Chauffage & climatisation | C10: Chauffage | D10: Poêle à bois / insert / foyer fermé | E10: 20-30 ans | F10: Oui | G10: Décret 2023-641 | H10: Annuel | I10: Pro qualifié | J10: Attestation d'entretien + certificat de ramonage | K10: 80-150 EUR | L10: Feu de cheminée, intoxication au CO | M10: =COUNTIF(Taches!$B$6:$B$250,$A10) -> 2 | N10: 1 | O10: Plaque signalétique | P10: Au dos ou sous l'appareil ; pour un insert, plaque souvent fixée dans l'habillage | Q10: Marque, modèle, puissance (kW), norme EN 13240 ou EN 13229 | R10: Insert encastré : plaque souvent inaccessible, utiliser la notice ou la facture
A11: CH-06 | B11: Chauffage & climatisation | C11: Chauffage | D11: Cheminée à foyer ouvert | E11: 30 ans et + | F11: Oui | G11: Décret 2023-641 : exempte d'entretien, ramonage obligatoire | H11: Ramonage annuel min. | I11: Pro qualifié | J11: Certificat de ramonage | K11: 60-120 EUR | L11: Feu de conduit, propagation à la charpente | M11: =COUNTIF(Taches!$B$6:$B$250,$A11) -> 1 | N11: 2 | O11: Document | P11: Pas de plaque | Q11: - | R11: Photographier le dernier certificat de ramonage
A12: CH-07 | B12: Chauffage & climatisation | C12: Chauffage | D12: Conduit de fumée | E12: 30-50 ans | F12: Oui | G12: Décret 2023-641 du 20/07/2023 (en vigueur 01/10/2023) | H12: 1/an min. ; 2/an si > 6 m3 de bois ou > 2,5 t de granules par an | I12: Pro qualifié (ramonage mécanique) | J12: Certificat de ramonage (conserver 5 ans) | K12: 60-120 EUR | L12: Amende 3e classe jusqu'à 450 EUR, refus assurance après sinistre | M12: =COUNTIF(Taches!$B$6:$B$250,$A12) -> 2 | N12: 1 | O12: Document | P12: Conduits récents : plaque du conduit près du raccordement ou dans les combles | Q12: Classe du conduit (température, résistance au feu), diamètre | R12: À défaut : certificat de ramonage
A13: CH-08 | B13: Chauffage & climatisation | C13: Chauffage | D13: Pompe à chaleur air/eau (4-70 kW) | E13: 15-20 ans | F13: Oui | G13: Décret 2020-912 + arrêté 24/07/2020 | H13: Tous les 2 ans | I13: Pro qualifié | J13: Attestation d'entretien | K13: 150-250 EUR | L13: Perte de COP, fuite de fluide frigorigene, casse compresseur | M13: =COUNTIF(Taches!$B$6:$B$250,$A13) -> 3 | N13: 1 | O13: Plaque signalétique | P13: Unité extérieure : flanc ou dos. Module intérieur : sous le capot avant ou sur le côté | Q13: Modèle, n. de série, puissance (kW), type de fluide (R32, R410A...), charge en kg et en t eq. CO2, mention hermétiquement scellé | R13: Fluide + charge + mention scellé déterminent le contrôle d'étanchéité : c'est ici que la photo calcule le statut légal
A14: CH-09 | B14: Chauffage & climatisation | C14: Chauffage | D14: Pompe à chaleur air/air réversible | E14: 12-15 ans | F14: Oui si >= 4 kW | G14: Décret 2020-912 (des 4 kW) | H14: Tous les 2 ans | I14: Pro qualifié | J14: Attestation d'entretien | K14: 120-200 EUR | L14: Qualité d'air dégradée, surconsommation, fuite de fluide | M14: =COUNTIF(Taches!$B$6:$B$250,$A14) -> 2 | N14: 1 | O14: Plaque signalétique | P14: Unité extérieure : flanc ou dos. Unité intérieure : sous le capot frontal ou sur le côté | Q14: Modèle, n. de série, puissance (kW), type de fluide (R32, R410A...), charge en kg et en t eq. CO2, mention hermétiquement scellé | R14: Fluide + charge + mention scellé déterminent le contrôle d'étanchéité : c'est ici que la photo calcule le statut légal
A15: CH-10 | B15: Chauffage & climatisation | C15: Chauffage | D15: PAC geothermique | E15: 20-25 ans | F15: Oui | G15: Décret 2020-912 | H15: Tous les 2 ans | I15: Pro qualifié | J15: Attestation d'entretien | K15: 200-350 EUR | L15: Déperdition du champ de captage, casse compresseur | M15: =COUNTIF(Taches!$B$6:$B$250,$A15) -> 1 | N15: 2 | O15: Plaque signalétique | P15: Flanc ou derrière le capot avant du module intérieur | Q15: Modèle, n. de série, puissance (kW), type de fluide (R32, R410A...), charge en kg et en t eq. CO2, mention hermétiquement scellé | R15: Fluide + charge + mention scellé déterminent le contrôle d'étanchéité : c'est ici que la photo calcule le statut légal
A16: CH-11 | B16: Chauffage & climatisation | C16: Chauffage | D16: Radiateurs à eau chaude | E16: 25-40 ans | F16: Non | G16: - | H16: Purge annuelle recommandée | I16: Particulier | J16: - | K16: 0 EUR | L16: Radiateurs froids en haut, surconsommation, bruits de circuit | M16: =COUNTIF(Taches!$B$6:$B$250,$A16) -> 2 | N16: 1 | O16: Aucune | P16: Pas de plaque exploitable | Q16: - | R16: Pas d'identification nécessaire
A17: CH-12 | B17: Chauffage & climatisation | C17: Chauffage | D17: Circuit de chauffage (desembouage) | E17: - | F17: Non | G17: - | H17: Tous les 8-10 ans recommandé | I17: Pro | J17: Facture / rapport | K17: 600-1200 EUR | L17: Boues = perte de rendement jusqu'à 15%, casse du circulateur | M17: =COUNTIF(Taches!$B$6:$B$250,$A17) -> 1 | N17: 2 | O17: Document | P17: Pas de plaque | Q17: - | R17: Photographier la facture du dernier desembouage
... A112: VEH-03 | B112: Vehicules | C112: Vehicules | D112: Vélo à assistance électrique | E112: 8-12 ans (batterie 4-6 ans) | F112: Non | G112: - | H112: Révision annuelle recommandée | I112: Particulier ou réparateur vélo | J112: Facture d'entretien | K112: 60-100 EUR | L112: Freinage dégradé, transmission usée, batterie abîmée par un stockage à plat ou à pleine charge | M112: =COUNTIF(Taches!$B$6:$B$250,$A112) -> 1 | N112: 3 | O112: Plaque signalétique | P112: Numéro de cadre gravé sous le pédalier ; étiquette sur le boîtier de la batterie | Q112: Marque, modèle, numéro de cadre, capacité de la batterie (Wh) | R112: Le numéro de cadre sert aussi en cas de vol

Sheet Taches
A2: Bibliotheque des taches d'entretien
A3: Le coeur du produit. La colonne Si non fait est ce qui declenche l'action chez l'utilisateur, bien plus que le rappel lui-meme.
A5: ID tache | B5: ID equip. | C5: Equipement | D5: Categorie | E5: Tache | F5: DIY / Pro | G5: Frequence (mois) | H5: Frequence (texte) | I5: Periode recommandee | J5: Duree (min) | K5: Outils et consommables | L5: Mode operatoire | M5: Si la tache n'est pas faite | N5: Obligation legale | O5: Palier | P5: Niveau d'entretien | Q5: Temps actif (min)
A6: T-001 | B6: CH-01 | C6: Chaudière gaz individuelle (4-400 kW) | D6: =IFERROR(INDEX(Equipements!$B$6:$B$200,MATCH($B6,Equipements!$A$6:$A$200,0)),"?") -> Chauffage & climatisation | E6: Entretien annuel par un professionnel | F6: Pro | G6: 12 | H6: Tous les 12 mois | I6: Août à octobre (avant la chauffe) | J6: 90 | K6: Prestataire qualifié PG | L6: Prendre rendez-vous hors pic saisonnier. Le technicien contrôle le corps de chauffe, le brûleur, les organes de sécurité, mesure le taux de CO et le rendement. Récupérer l'attestation sous 15 jours et l'archiver. | M6: Obligation légale non respectée, risque de CO, refus de prise en charge par l'assurance | N6: Oui | O6: Gratuit | P6: Obligation | Q6: 0
A7: T-002 | B7: CH-01 | C7: Chaudière gaz individuelle (4-400 kW) | D7: =IFERROR(INDEX(Equipements!$B$6:$B$200,MATCH($B7,Equipements!$A$6:$A$200,0)),"?") -> Chauffage & climatisation | E7: Contrôle de la pression du circuit | F7: DIY | G7: 1 | H7: Tous les mois | I7: Toute l'année | J7: 3 | K7: Aucun (manomètre intégré) | L7: Lire le manomètre à froid. Entre 1 et 1,5 bar en général. Si en dessous, ouvrir la vanne de remplissage jusqu'à 1,2 bar puis refermer. Si la pression rechute chaque semaine, il y a une fuite : appeler un professionnel. | M7: Mise en sécurité de la chaudière, arrêt du chauffage | N7: Non | O7: Gratuit | P7: Essentiel | Q7: 3
A8: T-003 | B8: CH-01 | C8: Chaudière gaz individuelle (4-400 kW) | D8: =IFERROR(INDEX(Equipements!$B$6:$B$200,MATCH($B8,Equipements!$A$6:$A$200,0)),"?") -> Chauffage & climatisation | E8: Purge du circulateur et vérification du vase d'expansion | F8: Pro | G8: 24 | H8: Tous les 2 ans | I8: Pendant l'entretien annuel | J8: 20 | K8: Manomètre, pompe à vélo | L8: À faire réaliser lors de l'entretien : contrôle de la pression de gonflage du vase (généralement 0,8 à 1 bar, circuit vide) et purge du circulateur. | M8: Vase crevé = variations de pression permanentes et fatigue du circuit | N8: Non | O8: Plus | P8: Recommande | Q8: 0
A9: T-004 | B9: CH-02 | C9: Chaudière fioul | D9: =IFERROR(INDEX(Equipements!$B$6:$B$200,MATCH($B9,Equipements!$A$6:$A$200,0)),"?") -> Chauffage & climatisation | E9: Entretien annuel chaudière fioul | F9: Pro | G9: 12 | H9: Tous les 12 mois | I9: Août à octobre | J9: 120 | K9: Prestataire qualifié | L9: Nettoyage du corps de chauffe et de la buse, remplacement du gicleur et du filtre fioul, réglage de la combustion avec analyseur, mesure de l'indice de noircissement. Attestation à archiver. | M9: Brûleur encrassé, surconsommation, panne en plein hiver | N9: Oui | O9: Gratuit | P9: Obligation | Q9: 0
A10: T-005 | B10: CH-02 | C10: Chaudière fioul | D10: =IFERROR(INDEX(Equipements!$B$6:$B$200,MATCH($B10,Equipements!$A$6:$A$200,0)),"?") -> Chauffage & climatisation | E10: Relevé du niveau de la cuve et commande anticipée | F10: DIY | G10: 1 | H10: Tous les mois | I10: Octobre à mars | J10: 5 | K10: Jauge | L10: Relever le niveau. Commander dès que la cuve descend sous 25% : les délais et les prix montent fortement en pleine saison de chauffe. | M10: Panne sèche, aspiration des boues de fond de cuve | N10: Non | O10: Gratuit | P10: Essentiel | Q10: 5
A11: T-006 | B11: CH-03 | C11: Chaudière bois / granules | D11: =IFERROR(INDEX(Equipements!$B$6:$B$200,MATCH($B11,Equipements!$A$6:$A$200,0)),"?") -> Chauffage & climatisation | E11: Entretien annuel chaudière bois / granules | F11: Pro | G11: 12 | H11: Tous les 12 mois | I11: Août à septembre | J11: 120 | K11: Prestataire qualifié | L11: Nettoyage complet de l'échangeur, du foyer et du système d'extraction des cendres, contrôle des sondes et de la vis sans fin, réglage de la combustion. | M11: Perte de rendement, blocage de la vis d'alimentation | N11: Oui | O11: Gratuit | P11: Obligation | Q11: 0
A12: T-007 | B12: CH-03 | C12: Chaudière bois / granules | D12: =IFERROR(INDEX(Equipements!$B$6:$B$200,MATCH($B12,Equipements!$A$6:$A$200,0)),"?") -> Chauffage & climatisation | E12: Vidage du cendrier | F12: DIY | G12: 1 | H12: Toutes les 2 à 6 semaines selon usage | I12: Octobre à avril | J12: 10 | K12: Aspirateur à cendres | L12: Laisser refroidir complètement. Aspirer avec un aspirateur à cendres uniquement (jamais un aspirateur domestique). Vérifier que le cendrier est bien reclipse. | M12: Débordement dans le foyer, combustion dégradée | N12: Non | O12: Gratuit | P12: Essentiel | Q12: 10
A13: T-008 | B13: CH-04 | C13: Poêle à granules | D13: =IFERROR(INDEX(Equipements!$B$6:$B$200,MATCH($B13,Equipements!$A$6:$A$200,0)),"?") -> Chauffage & climatisation | E13: Nettoyage du creuset et de la vitre | F13: DIY | G13: 0.25 | H13: Toutes les semaines en saison | I13: Octobre à avril | J13: 15 | K13: Aspirateur à cendres, grattoir, chiffon | L13: Appareil froid. Retirer le creuset, gratter les trous d'arrivée d'air un par un, aspirer le logement. Nettoyer la vitre avec de la cendre humide sur du papier journal. | M13: Trous obstrués = mauvaise combustion, extinction, code d'erreur | N13: Non | O13: Gratuit | P13: Essentiel | Q13: 15
A14: T-009 | B14: CH-04 | C14: Poêle à granules | D14: =IFERROR(INDEX(Equipements!$B$6:$B$200,MATCH($B14,Equipements!$A$6:$A$200,0)),"?") -> Chauffage & climatisation | E14: Nettoyage de l'échangeur et des conduits internes | F14: DIY | G14: 1 | H14: Tous les mois en saison | I14: Octobre à avril | J14: 25 | K14: Aspirateur à cendres, ecouvillon fourni | L14: Actionner les tringles de decendrage si l'appareil en dispose, ouvrir les trappes de ramonage internes et aspirer. Se référer à la notice pour l'emplacement exact des trappes. | M14: Échangeur encrassé = jusqu'à 20% de rendement perdu | N14: Non | O14: Gratuit | P14: Recommande | Q14: 25
A15: T-010 | B15: CH-04 | C15: Poêle à granules | D15: =IFERROR(INDEX(Equipements!$B$6:$B$200,MATCH($B15,Equipements!$A$6:$A$200,0)),"?") -> Chauffage & climatisation | E15: Entretien annuel complet par un professionnel | F15: Pro | G15: 12 | H15: Tous les 12 mois | I15: Août à septembre | J15: 90 | K15: Prestataire qualifié | L15: Démontage, nettoyage des ventilateurs et du bougeoir, contrôle des joints, de la sonde de température et du pressostat, mise à jour des paramètres de combustion. | M15: Obligation légale, usure prématurée, arrêt en pleine saison | N15: Oui | O15: Gratuit | P15: Obligation | Q15: 0
A16: T-011 | B16: CH-04 | C16: Poêle à granules | D16: =IFERROR(INDEX(Equipements!$B$6:$B$200,MATCH($B16,Equipements!$A$6:$A$200,0)),"?") -> Chauffage & climatisation | E16: Remplacement des joints de porte et de vitre | F16: Pro | G16: 36 | H16: Tous les 3 ans | I16: Hors saison | J16: 30 | K16: Kit de joints, colle réfractaire | L16: À faire réaliser lors de l'entretien annuel. Test préalable : glisser une feuille de papier dans la porte fermée, si elle coulisse sans résistance, le joint est à changer. | M16: Entrée d'air parasite, combustion incontrôlée, surconsommation | N16: Non | O16: Plus | P16: Recommande | Q16: 0
A17: T-012 | B17: CH-05 | C17: Poêle à bois / insert / foyer fermé | D17: =IFERROR(INDEX(Equipements!$B$6:$B$200,MATCH($B17,Equipements!$A$6:$A$200,0)),"?") -> Chauffage & climatisation | E17: Nettoyage de la vitre et du foyer | F17: DIY | G17: 0.25 | H17: Toutes les semaines en saison | I17: Octobre à avril | J17: 15 | K17: Cendre, papier journal, aspirateur à cendres | L17: Laisser un lit de cendres de 2 à 3 cm au fond du foyer : il favorise la combustion. Nettoyer la vitre avec du papier journal humidifié trempé dans la cendre. | M17: Vitre opaque, mauvais tirage | N17: Non | O17: Gratuit | P17: Recommande | Q17: 15
... A159: T-154 | B159: VEH-03 | C159: Vélo à assistance électrique | D159: =IFERROR(INDEX(Equipements!$B$6:$B$200,MATCH($B159,Equipements!$A$6:$A$200,0)),"?") -> Vehicules | E159: Révision annuelle du vélo électrique | F159: Pro | G159: 12 | H159: Tous les ans | I159: Printemps | J159: 60 | K159: Réparateur vélo | L159: Contrôle des freins, de la transmission et des pneus, mise à jour du moteur si le fabricant la propose. Entre deux périodes d'usage, stocker la batterie à mi-charge, au sec et à température ambiante. | M159: Freinage dégradé, usure accélérée de la transmission, batterie qui perd de sa capacité | N159: Non | O159: Gratuit | P159: Essentiel | Q159: 0

Sheet Questionnaire
A2: Questionnaire d'accueil : premiere utilisation et nouveau lieu
A3: Une ligne = une reponse possible. Chaque obligation a sa propre question de date (onglet Questions de date, seed/date_questions.json), qui nomme l'appareil et l'intervention. Réponses graduées avec le vrai délai de l'obligation : mois et année → calcul normal ; « Il y a moins de {délai} », sans date précise → à confirmer (orange) ; « Il y a plus de {délai} » → en retard (rouge) ; « Jamais ou je ne sais pas », un seul bouton en dernière position → en retard, prioritaire. Les dates se choisissent dans deux listes (mois en toutes lettres, année) et s'affichent « septembre 2026 », jamais avec un jour.
A5: ID | B5: Bloc | C5: Ordre | D5: Question | E5: Type de reponse | F5: Reponse | G5: Types crees | H5: Question de suivi | I5: Aide | J5: Suivi : types crees si oui | K5: Ne pas poser si | L5: Renseigne | M5: Statut initial
A6: Q01 | B6: Contexte | C6: 1 | D6: Ce logement est : | E6: Choix unique | F6: Votre résidence principale | G6: - | H6: - | I6: Type de bien : résidence principale. | J6: - | K6: - | L6: property_type = main_home | M6: -
A7: Q01 | B7: Contexte | C7: 1 | D7: Ce logement est : | E7: Choix unique | F7: Une résidence secondaire | G7: - | H7: - | I7: Active les tâches d'hivernage et de remise en service. | J7: - | K7: - | L7: property_type = second_home | M7: -
A8: Q01 | B8: Contexte | C8: 1 | D8: Ce logement est : | E8: Choix unique | F8: Un logement loué à l'année | G8: - | H8: - | I8: Les tâches à la charge de l'occupant (entretien de la chaudière, ramonage, entretien du détecteur) reviennent au locataire : elles sont affichées pour information. | J8: - | K8: - | L8: property_type = long_term_rental | M8: -
A9: Q01 | B9: Contexte | C9: 1 | D9: Ce logement est : | E9: Choix unique | F9: Un logement loué en courte durée | G9: - | H9: - | I9: Toutes les obligations restent à votre charge. | J9: - | K9: - | L9: property_type = short_term_rental | M9: -
A10: Q02 | B10: Obligations | C10: 2 | D10: Comment le logement est-il principalement chauffé ? | E10: Choix unique | F10: Chaudière au gaz de ville | G10: CH-01 | H10: Est-elle raccordée à un conduit de cheminée, et non à une ventouse (un tuyau qui sort directement du mur) ? | I10: - | J10: CH-07 | K10: - | L10: - | M10: -
A11: Q02 | B11: Obligations | C11: 2 | D11: Comment le logement est-il principalement chauffé ? | E11: Choix unique | F11: Chaudière au propane (citerne) | G11: CH-01, CH-16 | H11: Est-elle raccordée à un conduit de cheminée, et non à une ventouse (un tuyau qui sort directement du mur) ? | I11: - | J11: CH-07 | K11: - | L11: - | M11: -
A12: Q02 | B12: Obligations | C12: 2 | D12: Comment le logement est-il principalement chauffé ? | E12: Choix unique | F12: Chaudière au fioul | G12: CH-02, CH-15, CH-07 | H12: - | I12: Crée aussi la cuve et le conduit de fumée. | J12: - | K12: - | L12: - | M12: -
A13: Q02 | B13: Obligations | C13: 2 | D13: Comment le logement est-il principalement chauffé ? | E13: Choix unique | F13: Chaudière bois ou granulés | G13: CH-03, CH-07 | H13: - | I13: Crée aussi le conduit de fumée. | J13: - | K13: - | L13: - | M13: -
A14: Q02 | B14: Obligations | C14: 2 | D14: Comment le logement est-il principalement chauffé ? | E14: Choix unique | F14: Poêle ou insert à bois | G14: CH-05, CH-07 | H14: - | I14: Crée aussi le conduit de fumée. | J14: - | K14: - | L14: - | M14: -
A15: Q02 | B15: Obligations | C15: 2 | D15: Comment le logement est-il principalement chauffé ? | E15: Choix unique | F15: Poêle à granulés | G15: CH-04, CH-07 | H15: - | I15: Crée aussi le conduit de fumée. | J15: - | K15: - | L15: - | M15: -
A16: Q02 | B16: Obligations | C16: 2 | D16: Comment le logement est-il principalement chauffé ? | E16: Choix unique | F16: Pompe à chaleur avec radiateurs ou plancher chauffant | G16: CH-08 | H16: - | I16: Pompe à chaleur air/eau. | J16: - | K16: - | L16: - | M16: -
A17: Q02 | B17: Obligations | C17: 2 | D17: Comment le logement est-il principalement chauffé ? | E17: Choix unique | F17: Pompe à chaleur qui souffle de l'air (clim réversible) | G17: CH-09 | H17: - | I17: Obligation à confirmer selon la puissance, à partir de 4 kW. | J17: - | K17: - | L17: - | M17: -
... A89: Q20 | B89: Entretien | C89: 20 | D89: Quels appareils avez-vous ? | E89: Cases a cocher | F89: Gouttières | G89: BAT-02 | H89: - | I89: - | J89: - | K89: Q19 = Non, plus tard | L89: - | M89: -

Sheet Questions de date
A2: Une question de date par obligation, avec le vrai delai legal
A3: Mois gradue : mois et annee | Il y a moins de {delai} | Il y a plus de {delai} | Jamais ou je ne sais pas (un seul bouton, en dernier). Affichage des dates : septembre 2026.
A5: Cle | B5: Taches | C5: Appareil | D5: Question | E5: Type | F5: Delai | G5: Note
A6: T-001 | B6: T-001 | C6: Chaudière au gaz | D6: Quand la chaudière a-t-elle été entretenue pour la dernière fois ? | E6: Mois gradué | F6: un an | G6: -
A7: T-004 | B7: T-004 | C7: Chaudière au fioul | D7: Quand la chaudière a-t-elle été entretenue pour la dernière fois ? | E7: Mois gradué | F7: un an | G7: -
A8: T-006 | B8: T-006 | C8: Chaudière bois ou granulés | D8: Quand la chaudière a-t-elle été entretenue pour la dernière fois ? | E8: Mois gradué | F8: un an | G8: -
A9: T-010 | B9: T-010 | C9: Poêle à granulés | D9: Quand le poêle à granulés a-t-il été entretenu pour la dernière fois ? | E9: Mois gradué | F9: un an | G9: -
A10: T-013 | B10: T-013 | C10: Poêle ou insert à bois | D10: Quand le poêle ou l'insert a-t-il été entretenu pour la dernière fois ? | E10: Mois gradué | F10: un an | G10: -
A11: T-014 | B11: T-014 | C11: Conduit de fumée | D11: Quand le conduit de fumée a-t-il été ramoné pour la dernière fois ? | E11: Mois gradué | F11: un an | G11: Posée seule quand l'appareil et le conduit ont été faits à des dates différentes.
A12: T-016 | B12: T-016 | C12: Cheminée à foyer ouvert | D12: Quand la cheminée a-t-elle été ramonée pour la dernière fois ? | E12: Mois gradué | F12: un an | G12: -
A13: T-001+T-014 | B13: T-001, T-014 | C13: Chaudière au gaz et son conduit | D13: Quand la chaudière a-t-elle été entretenue et son conduit ramoné pour la dernière fois ? | E13: Mois gradué | F13: un an | G13: Question commune à l'appareil et à son conduit (REGLE-03).
A14: T-004+T-014 | B14: T-004, T-014 | C14: Chaudière au fioul et son conduit | D14: Quand la chaudière a-t-elle été entretenue et son conduit ramoné pour la dernière fois ? | E14: Mois gradué | F14: un an | G14: Question commune à l'appareil et à son conduit (REGLE-03).
A15: T-006+T-014 | B15: T-006, T-014 | C15: Chaudière bois ou granulés et son conduit | D15: Quand la chaudière a-t-elle été entretenue et son conduit ramoné pour la dernière fois ? | E15: Mois gradué | F15: un an | G15: Question commune à l'appareil et à son conduit (REGLE-03).
A16: T-010+T-014 | B16: T-010, T-014 | C16: Poêle à granulés et son conduit | D16: Quand le poêle à granulés a-t-il été entretenu et son conduit ramoné pour la dernière fois ? | E16: Mois gradué | F16: un an | G16: Question commune à l'appareil et à son conduit (REGLE-03).
... A41: T-015 | B41: T-015 | C41: Conduit de fumée | D41: - | E41: Non générée | F41: - | G41: Second ramonage : seulement au-delà de 6 m³ de bois ou 2,5 t de granulés par an.

Sheet Plaques par marque
A2: Aide adaptative a la marque : ou lire la plaque et quel identifiant valider
A3: Maintenu par groupe industriel : une dizaine de groupes couvrent l'essentiel du parc francais. Colonne Statut : ne pousser en production que les lignes verifiees.
A5: Groupe | B5: Marques couvertes | C5: Categories | D5: Identifiants a lire | E5: Regle de validation (indicative) | F5: Decodage date de fabrication | G5: Emplacements specifiques | H5: Particularites | I5: Source | J5: Statut
A6: BSH | B6: Bosch, Siemens, Neff, Gaggenau, Constructa | C6: Lavage, froid, cuisson, hottes | D6: E-Nr (référence modèle), FD (date de fabrication), Z-Nr / n. de série | E6: E-Nr : alphanumérique terminé par / et 1 à 2 chiffres (ex. B57CR22N0/01). FD : 4 chiffres | F6: Année = 2 premiers chiffres du FD + 1920 ; mois = 2 derniers (FD 9405 = mai 2014). Règle publiée jusqu'à FD 9912 (dec. 2019) : format postérieur à confirmer auprès de BSH | G6: Localisateur officiel par catégorie sur les sites de chaque marque ; en général au niveau de la porte | H6: Bosch propose déjà la lecture photo de sa plaque sur son site : preuve de faisabilité et benchmark | I6: https://www.bosch-home.fr/france/localiser-plaque-signaletique ; https://www.neff-home.com/fr/promotions/plaque-signaletique | J6: Vérifié (source officielle)
A7: Miele | B7: Miele | C7: Tout le gros électroménager | D7: Référence du modèle, numéro de matériel, numéro de fabrication, numéro de série | E7: Format propre à Miele | F7: À documenter | G7: Tables de cuisson : plaque SOUS l'appareil | H7: Une 2e plaque est fournie pour être collée dans le mode d'emploi : c'est elle qu'il faut photographier pour une table encastrée | I7: https://www.miele.fr/c/plate-finder.htm | J7: Vérifié (source officielle)
A8: Liebherr | B8: Liebherr | C8: Réfrigérateurs, congélateurs, caves à vin | D8: Service no. et Serial no. | E8: Numéro à 9 chiffres (selon Liebherr) | F8: À documenter | G8: Plaque à l'intérieur de l'appareil | H8: Modèles à écran : plaque signalétique numérique dans Réglages > Informations. Une capture de l'écran suffit, sans chercher la plaque | I8: https://www.liebherr.com/fr-fr/refrigerateurs-congelateurs/plaque-signaletique-3042050 | J8: Vérifié (source officielle)
A9: Samsung | B9: Samsung | C9: Lavage, froid, cuisson, climatisation | D9: Code modèle, n. de série (S/N) | E9: Format propre à Samsung | F9: À documenter | G9: Froid : paroi gauche, intérieure ou extérieure. Lavage frontal : cadre de porte près du joint, sinon étiquette au dos | H9: Sur certains réfrigérateurs, le numéro de l'autocollant extérieur est un numéro de contrôle usine, pas le n. de série : lire l'étiquette intérieure | I9: https://ushl.samsung.com/ch_fr/support/home-appliances/comment-trouver-le-numero-de-serie-code-modele-ou-numero-imei-de-mon-appareil ; https://ushl.samsung.com/be_fr/support/home-appliances/ou-puis-je-trouver-le-numero-de-serie-de-mon-refrigerateur | J9: Vérifié (source officielle)
A10: LG | B10: LG | C10: Lavage, froid, cuisson, climatisation | D10: Modèle, n. de série | E10: Format propre à LG | F10: À documenter | G10: Lavage frontal : étiquette argentée autour de l'ouverture du tambour, en général en haut. Chargement par le haut : au dos ou côté droit. Froid : paroi intérieure gauche (modèles récents), droite (anciens) | H10: - | I10: https://www.lg.com/africa_fr/support/aide-produit/CT40007876-20155091574353 ; https://www.lg.com/us/support/help-library/lg-refrigerator-how-to-find-my-lg-model-and-serial-number--20154743175875 | J10: Vérifié (source officielle)
A11: Whirlpool (fabrication Whirlpool) | B11: Whirlpool, Bauknecht, Ignis, Laden, une partie des appareils Ikea | C11: Lavage, froid, cuisson | D11: Code service 12NC, n. de série | E11: Code service : 12 chiffres commençant par 85 | F11: À documenter | G11: Plaque visible porte ouverte (lavage), paroi intérieure (froid) | H11: Ikea : le fabricant réel varie selon le modèle, le format de l'identifiant révèle lequel. Activités européennes de Whirlpool reprises par Beko Europe | I11: https://www.boulanger.com/ref/9000518317 | J11: Source secondaire (distributeur)
A12: Ex-Indesit Company | B12: Indesit, Hotpoint, Ariston (électroménager), Scholtes | C12: Lavage, froid, cuisson | D12: Modèle, code article, n. de série | E12: Code article : F suivi de 6 chiffres (ex. F078786) ; productions récentes : code numérique à 12 chiffres | F12: À documenter | G12: Plaque visible porte ouverte (lavage), paroi intérieure (froid) | H12: Deux générations de formats coexistent dans le parc installé | I12: https://www.boulanger.com/ref/9000542389 | J12: Source secondaire (à confirmer)
A13: Electrolux | B13: Electrolux, AEG, Zanussi, Faure, Arthur Martin | C13: Lavage, froid, cuisson | D13: Modèle, PNC (code produit), n. de série | E13: PNC numérique : longueur à confirmer avant d'en faire une règle de validation | F13: À documenter | G13: Cadre du hublot (lavage), chant de porte (lave-vaisselle), paroi intérieure (froid) | H13: Le PNC est indispensable pour commander une pièce détachée d'origine | I13: https://notices.underdog.shop/user-manuals/7332543124978-8da7de9f-4c2d-48eb-9c88-224de49afc0f.pdf | J13: Partiellement vérifié (notice fabricant)
A14: Vaillant Group | B14: Saunier Duval, Vaillant | C14: Chaudières, chauffe-eau, PAC | D14: Gamme et modèle, n. de série, puissance, année | E14: Format propre au fabricant | F14: À documenter | G14: Chaudière : sous le capot avant ou sur le flanc. Chauffe-eau : côté ou arrière | H14: Ne jamais déposer le capot d'un appareil gaz : relever la plaque lors de l'entretien annuel ou sur l'attestation | I14: https://selectra.info/energie/renovation-energetique/marque-chaudiere/saunier-duval | J14: Source secondaire
A15: PAC et climatisation (toutes marques) | B15: Daikin, Mitsubishi Electric, Atlantic, Panasonic, Toshiba, etc. | C15: Climatisation, PAC, chauffe-eau thermodynamique | D15: Modèle, n. de série, puissance, type de fluide, charge en kg et en t eq. CO2, mention hermétiquement scellé | E15: Charge x PRG du fluide = t eq. CO2 : seuil de contrôle d'étanchéité à 5 t eq. CO2 | F15: - | G15: Unité extérieure : flanc ou dos. Unité intérieure : sous le capot frontal ou sur le côté | H15: En résidentiel, un équipement étiqueté hermétiquement scellé contenant moins de 3 kg de gaz fluores est exempte de contrôle d'étanchéité | I15: http://data.europa.eu/eli/reg/2024/573/oj ; https://œil.europarl.europa.eu/œil/fr/document-summary?id=1772308 | J15: Vérifié (texte réglementaire) ; emplacements génériques
A16: Beko Europe (Arcelik) | B16: Beko, Grundig | C16: Lavage, froid, cuisson | D16: À documenter | E16: À documenter | F16: À documenter | G16: Emplacements génériques par catégorie | H16: - | I16: - | J16: À documenter
... A22: Petit électroménager | B22: Groupe SEB (Rowenta, Moulinex, Krups, Tefal), De'Longhi, Dyson, Philips | C22: Café, aspirateurs, repassage | D22: À documenter | E22: À documenter | F22: À documenter | G22: Sous l'appareil | H22: - | I22: - | J22: À documenter

Sheet Obligations legales
A2: Obligations reglementaires - logement en France
A3: Etat du droit verifie en septembre 2026. A revoir chaque annee : ces textes bougent souvent.
A5: ID | B5: Obligation | C5: Equipements concernes | D5: Texte de reference | E5: Frequence | F5: Qui est redevable | G5: Justificatif | H5: Sanction ou risque | I5: Source | J5: Amende maximale | K5: Assurance | L5: Responsabilite | M5: Danger | N5: Autre consequence
A6: L-01 | B6: Entretien annuel des chaudières 4-400 kW | C6: Chaudière gaz, fioul, bois, charbon, multicombustible (CH-01, CH-02, CH-03, ECS-03) | D6: Décret n. 2009-649 du 09/06/2009 + arrêté du 15/09/2009 ; C. env. art. R224-41-4 à R224-41-9 | E6: Tous les 12 mois | F6: Occupant pour les chaudières individuelles ; propriétaire ou syndicat pour les collectives (sauf clause contraire du bail) | G6: Attestation d'entretien remise par le professionnel sous 15 jours, à conserver au moins 2 ans | H6: Pas d'amende directe, mais retenue possible sur le dépôt de garantie et réduction ou refus d'indemnisation par l'assureur en cas de sinistre | I6: https://www.service-public.gouv.fr/particuliers/vosdroits/F20760 | J6: - | K6: Indemnisation réduite ou refusée après un sinistre | L6: - | M6: Intoxication au monoxyde de carbone | N6: Retenue possible sur le dépôt de garantie (locataire)
A7: L-02 | B7: Ramonage des conduits de fumée | C7: Tout conduit raccordé à un appareil à combustion : le conduit de fumée (CH-07) et la cheminée à foyer ouvert (CH-06) | D7: Décret n. 2023-641 du 20/07/2023 + arrêté du 20/07/2023, en vigueur au 01/10/2023 ; Code de la santé publique | E7: 1 ramonage mécanique tous les 12 mois minimum. 2e ramonage requis au-delà de 6 m3 de bois ou 2,5 t de granules consommés dans l'année. Appareils collectifs : tous les 6 mois | F7: Occupant (décret n. 87-712 sur les réparations locatives) ; syndic pour les conduits collectifs | G7: Certificat de ramonage délivré par un professionnel qualifié, à conserver 5 ans | H7: Amende de 3e classe jusqu'à 450 EUR ; refus d'indemnisation en cas de feu de cheminée. Le ramonage chimique (bûche) n'a aucune valeur juridique | I7: https://www.legifrance.gouv.fr/jorf/id/JORFTEXT000047867286 | J7: Jusqu'à 450 € | K7: Refus d'indemnisation après un feu de cheminée | L7: - | M7: Feu de conduit, intoxication au monoxyde de carbone | N7: Un ramonage chimique ne vaut pas preuve
A8: L-03 | B8: Entretien des appareils à combustible solide | C8: Poêle à granules, poêle à bois, insert, foyer fermé, cuisinière (CH-04, CH-05) | D8: Décret n. 2023-641 du 20/07/2023 | E8: Tous les 12 mois pour les appareils individuels | F8: Occupant | G8: Attestation d'entretien | H8: Non-conformité, difficultés avec l'assureur. Les foyers ouverts sont exemptés d'entretien mais restent soumis au ramonage | I8: https://www.legifrance.gouv.fr/jorf/id/JORFTEXT000047867286 | J8: - | K8: Difficultés d'indemnisation après un sinistre | L8: - | M8: Incendie, intoxication au monoxyde de carbone | N8: -
A9: L-04 | B9: Entretien des systèmes thermodynamiques 4-70 kW | C9: PAC air/eau, air/air, geothermique, chauffe-eau thermodynamique, climatiseur, PAC de piscine (CH-08 à CH-10, ECS-02, CLIM-01, PIS-05) | D9: Décret n. 2020-912 du 28/07/2020 + arrêté du 24/07/2020 ; C. env. art. R224-44 à R224-44-5 | E9: Au moins tous les 2 ans | F9: Propriétaire ou occupant selon le bail | G9: Attestation d'entretien | H9: Non-conformité ; perte de garantie constructeur fréquente en l'absence d'entretien | I9: https://www.ecologie.gouv.fr/politiques-publiques/entretien-inspection-systemes-chauffage-climatisation | J9: - | K9: - | L9: - | M9: - | N9: Perte fréquente de la garantie constructeur
A10: L-05 | B10: Inspection périodique des systèmes > 70 kW | C10: Systèmes thermodynamiques et de ventilation combinés à un chauffage par effet joule > 70 kW | D10: Décret n. 2020-912 ; C. env. art. R224-45 à R224-45-9 | E10: Au moins tous les 5 ans | F10: Propriétaire ou syndicat de copropriété | G10: Rapport d'inspection | H10: Non-conformité. Concerne surtout le collectif et le tertiaire | I10: https://www.ecologie.gouv.fr/politiques-publiques/entretien-inspection-systemes-chauffage-climatisation | J10: - | K10: - | L10: - | M10: - | N10: Non-conformité (surtout en collectif et tertiaire)
A11: L-06 | B11: Contrôle d'étanchéité des fluides frigorigenes | C11: Tout équipement dont la charge atteint 5 tonnes équivalent CO2 (CLIM-03) | D11: Règlement (UE) 2024/573 du 07/02/2024 dit F-Gas, applicable depuis le 11/03/2024 (abroge le règlement 517/2014) | E11: Tous les 12 mois pour 5 à 50 t CO2 eq (fréquence resserrée au-delà). En résidentiel, exemption pour un équipement étiqueté hermétiquement scellé contenant moins de 3 kg | F11: Exploitant / propriétaire de l'équipement | G11: Fiche d'intervention CERFA 15497, opérateur titulaire d'une attestation de capacité | H11: Sanction administrative ; impact climatique (le R410A à un pouvoir de réchauffement environ 2000 fois celui du CO2) | I11: http://data.europa.eu/eli/reg/2024/573/oj | J11: Sanction administrative | K11: - | L11: - | M11: - | N11: Fuite d'un gaz à fort effet de serre
A12: L-07 | B12: Détecteur autonome avertisseur de fumée (DAAF) | C12: Tout logement (SEC-01) | D12: Loi n. 2010-238 du 09/03/2010 ; CCH art. R129-12 à R129-15 | E12: Installation par le propriétaire ; entretien, test et remplacement des piles par l'occupant ; appareil à remplacer au bout de 10 ans | F12: Propriétaire pour la fourniture et l'installation, occupant pour l'entretien | G12: Attestation à transmettre à l'assureur | H12: Pas d'amende prévue, mais l'assureur peut opposer le défaut d'installation | I12: https://www.service-public.gouv.fr/particuliers/vosdroits/F19871 | J12: - | K12: L'assureur peut opposer l'absence de détecteur | L12: - | M12: Incendie non détecté | N12: -
A13: L-08 | B13: Sécurité des piscines privatives enterrées | C13: Piscine enterrée ou semi-enterrée non close, à usage individuel ou collectif (PIS-01, PIS-07) | D13: Loi n. 2003-9 du 03/01/2003 ; CCH art. L128-1 et R128-1 | E13: Dispositif normalisé en place en permanence : barrière NF P90-306, alarme NF P90-307, couverture NF P90-308 ou abri NF P90-309 | F13: Propriétaire | G13: Attestation de conformité du dispositif, note technique du constructeur | H13: Amende jusqu'à 45 000 EUR ; responsabilité pénale en cas de noyade | I13: https://www.service-public.gouv.fr/particuliers/vosdroits/F2062 | J13: Jusqu'à 45 000 € | K13: - | L13: Pénale en cas de noyade | M13: Noyade d'enfant | N13: -
A14: L-09 | B14: Contrôle de l'assainissement non collectif | C14: Fosse toutes eaux, fosse septique, micro-station (ASS-01, ASS-02) | D14: Code de la santé publique art. L1331-1-1 ; arrêtés du 27/04/2012 et du 07/09/2009 | E14: Contrôle périodique du SPANC au moins tous les 10 ans (la commune peut imposer un intervalle plus court, souvent 4 à 8 ans). Vidange dès que les boues atteignent 50% du volume utile | F14: Propriétaire | G14: Rapport de visite du SPANC ; bordereau de suivi des matières de vidange par un vidangeur agréé | H14: Mise en demeure, travaux imposés sous 4 ans, majoration de la redevance jusqu'à 100%. À la vente, rapport de moins de 3 ans obligatoire | I14: https://www.service-public.gouv.fr/particuliers/vosdroits/F1400 | J14: - | K14: - | L14: - | M14: - | N14: Travaux imposés sous 4 ans, redevance majorée jusqu'à 100 %, rapport exigé à la vente
A15: L-10 | B15: Déclaration des puits et forages domestiques | C15: Puits, forage, captage privé (EAU-05) | D15: CGCT art. L2224-9 ; décret n. 2008-652 du 02/07/2008 | E15: Déclaration en mairie avant travaux et à l'achèvement ; contrôle si l'ouvrage est relié au réseau intérieur | F15: Propriétaire | G15: Récépissé de déclaration (CERFA 13837) | H15: Amende ; obligation de déconnexion du réseau | I15: https://www.service-public.gouv.fr/particuliers/vosdroits/F31864 | J15: Amende possible | K15: - | L15: - | M15: - | N15: Déconnexion du réseau exigée
A16: L-11 | B16: Diagnostic de l'installation intérieure de gaz | C16: Installation intérieure de gaz de plus de 15 ans (ENE-06) | D16: CCH art. L271-4 ; arrêté du 06/04/2007 | E16: À la vente : validité 3 ans. En location : validité 6 ans | F16: Vendeur ou bailleur | G16: Diagnostic réalisé par un diagnostiqueur certifié | H16: Responsabilité du vendeur pour vice caché si le diagnostic est absent ou erroné | I16: https://www.service-public.gouv.fr/particuliers/vosdroits/F16158 | J16: - | K16: - | L16: Civile (vice caché) à la vente | M16: - | N16: Vente ou location sans diagnostic valide
... A26: L-21 | B26: Contrôle technique des deux-roues, trois-roues et quadricycles motorisés | C26: Véhicules de catégorie L : motos, scooters, cyclomoteurs, quadricycles (VEH-02). Les vélos à assistance électrique ne sont pas concernés | D26: Décret n. 2023-974 du 23/10/2023 ; arrêté du 23/10/2023 | E26: Véhicules immatriculés depuis 2022 : premier contrôle entre 4 ans et demi et 5 ans après la mise en circulation, puis tous les 3 ans. Véhicules plus anciens : calendrier transitoire selon l'année d'immatriculation | F26: Propriétaire du véhicule | G26: Procès-verbal de contrôle technique | H26: Amende de 135 EUR | I26: https://www.service-public.gouv.fr/particuliers/actualites/A16861 ; https://www.info.gouv.fr/actualite/controle-technique-obligatoire-pour-les-deux-roues | J26: 135 € | K26: - | L26: - | M26: - | N26: -

Sheet Referentiel
A2: Nomenclatures pour le modele de donnees
A3: Valeurs a reprendre telles quelles dans les tables de l'application.
A5: Table | B5: Cle | C5: Libelle | D5: Commentaire
A6: Categorie | B6: kitchen | C6: Cuisine
A7: Categorie | B7: laundry | C7: Buanderie
A8: Categorie | B8: heating_cooling | C8: Chauffage & climatisation
A9: Categorie | B9: small_appliances | C9: Petit electromenager
A10: Categorie | B10: electronics | C10: Electronique | D10: Pas de plan d'entretien : garantie et documents
A11: Categorie | B11: garden_pool | C11: Jardin & piscine
A12: Categorie | B12: home_safety | C12: Maison & securite
A13: Categorie | B13: energy | C13: Energie
A14: Categorie | B14: vehicles | C14: Vehicules | D14: v1 : garantie, documents, controle technique ; revisions au kilometrage plus tard
A15: Categorie | B15: other | C15: Autre | D15: Pas de plan d'entretien : garantie et documents
A16: TypeIntervenant | B16: diy | C16: Realisable par l'occupant | D16: Eligible au palier gratuit
A17: TypeIntervenant | B17: pro | C17: Professionnel requis | D17: Matiere premiere du palier Care
A18: TypeIntervenant | B18: pro_certifie | C18: Professionnel certifie | D18: Fluides frigorigenes, gaz, ascenseur, ramonage
A19: RegleFrequence | B19: every_n_months | C19: Tous les N mois | D19: Couvre la quasi-totalite des cas
A20: RegleFrequence | B20: season_anchor | C20: Ancree sur une saison | D20: Ex. avant la saison de chauffe
A21: RegleFrequence | B21: per_use | C21: A chaque utilisation | D21: Filtre de seche-linge, prefiltre de pompe
A22: RegleFrequence | B22: threshold | C22: Sur seuil mesure | D22: Taux de boues, consommation de bois, date de peremption
A23: StatutTache | B23: a_venir | C23: A venir
A24: StatutTache | B24: due | C24: Echue
A25: StatutTache | B25: en_retard | C25: En retard | D25: Declencheur de relance et, si Care, de proposition d'intervention
A26: StatutTache | B26: faite | C26: Realisee | D26: Horodatee, alimente l'historique d'entretien
A27: StatutTache | B27: reportee | C27: Reportee | D27: Limiter les reports successifs sur les taches legales
A28: StatutTache | B28: non_applicable | C28: Non applicable | D28: L'utilisateur declare ne pas etre concerne
A29: Palier | B29: gratuit | C29: Gratuit | D29: Inventaire, rappels, mode operatoire
A30: Palier | B30: plus | C30: Plus | D30: Multi-biens, coffre-fort de documents, historique exportable
A31: Palier | B31: care | C31: Care | D31: Interventions a domicile programmees
A32: TypeJustificatif | B32: attestation_entretien | C32: Attestation d'entretien | D32: Chaudiere, PAC, appareil a combustible solide
A33: TypeJustificatif | B33: certificat_ramonage | C33: Certificat de ramonage | D33: A conserver 5 ans
A34: TypeJustificatif | B34: bordereau_vidange | C34: Bordereau de suivi de vidange | D34: Assainissement non collectif
A35: TypeJustificatif | B35: rapport_controle | C35: Rapport de controle | D35: SPANC, ascenseur, disconnecteur, cuve
A36: TypeJustificatif | B36: diagnostic | C36: Diagnostic reglementaire | D36: Gaz, electricite, termites
... A38: TypeJustificatif | B38: attestation_conformite | C38: Attestation de conformite | D38: Dispositif de securite piscine
A39: TypeBien | B39: residence_principale | C39: Residence principale
A40: TypeBien | B40: residence_secondaire | C40: Residence secondaire | D40: Hivernage et remise en service structurants
A41: TypeBien | B41: location_courte_duree | C41: Location courte duree | D41: Cible d'amorcage : plusieurs biens, panne = nuitee perdue
A42: TypeBien | B42: location_longue_duree | C42: Location longue duree | D42: Repartition proprietaire / locataire a gerer
A43: CiblePhoto | B43: plaque | C43: Plaque signaletique | D43: Identite de l'appareil, puissance, fluide
...
